Workbook

Sheet Enoncé
C5: BILAN
C6: ACTIFS | F6: PASSIFS
D7: VB | E7: Amortissements et dépréciations | F7: VNC
C8: ACTIF IMMOBILISÉ | G8: CAPITAUX PROPRES | H8: =SUM(H9:H12) -> 3388830
C9: CORPORELS | G9: Capital social | H9: 1600000
C10: Terrains | D10: 850000 | F10: 850000 | G10: Réserves | H10: 154520
C11: Constructions | D11: 480000 | E11: 355000 | F11: 125000 | G11: RAN | H11: 1245000
C12: Installations techniques | D12: 2860500 | E12: 1325000 | F12: 1535500 | G12: Résultat de l’année | H12: 389310
C13: Ordinateurs | D13: 19000 | E13: 8730 | F13: 10270
C14: Matériel de transport | D14: 300000 | E14: 83000 | F14: 217000 | G14: Provision pour R&C | H14: 15000
C15: INCORPORELS | G15: litige avec un salarié
C16: Frais d’établissement | D16: 20000 | E16: 15000 | F16: 5000
C17: Fonds de commerce | D17: 120000 | E17: 50000 | F17: 70000 | G17: DETTES | H17: =SUM(H18:H23) -> 2280440
C18: FINANCIERS | G18: Emprunt pool bancaire 1 | H18: 1550000
C19: Titres de participation | D19: 840000 | E19: 60000 | F19: 780000 | G19: Emprunt pool bancaire 2 | H19: 465000
C20: ACTIF CIRCULANT | G20: Dettes fournisseurs | H20: 190000
C21: Stocks | D21: 281300 | F21: 281300 | G21: Dettes sociales | H21: 20000
C22: Créances clients | D22: 454000 | E22: 22000 | F22: 432000 | G22: Dette de TVA collectée | H22: 40000
C23: Créances de TVA déductible | D23: 8200 | F23: 8200 | G23: Dette fiscale d'IS | H23: 15440
C24: Charges à répartir | D24: 20000 | F24: 20000
C25: VMP | D25: 730000 | F25: 730000
C26: Banque | D26: 620000 | F26: 620000
D27: =SUM(D10:D26) -> 7603000 | E27: 1918730 | F27: =D27-E27 -> 5684270 | H27: =SUM(H7:H26) -> 11353540
C39: CHARGES | E39: PRODUITS
C40: CHARGES D'EXPLOITATION | E40: PRODUITS D'EXPLOITATION
C41: Achat MP et emballages, consommables | D41: 1950000 | E41: Vente de produits finis | F41: 3233333
C43: Variation des stocks | D43: -45000
C44: Achats non stockés | D44: 55600
C45: Prestations externes de maintenance | D45: 35600
C46: Frais de personnel | D46: 475000
C49: Dotation aux amortissements | D49: 162720
C50: Dotation aux provisions | D50: 12000
C52: Dotation aux provisions pour R&C | D52: 15000
C56: CHARGES FINANCIERES | E56: PRODUITS FINANCIERS
C57: Charges d'intérêts | D57: 58000 | E57: Dividendes reçus des participations | F57: 3500
C60: IS | D60: 128603
D66: =D60+D57+D52+D50+D49+D46+D45+D44+D43+D41 -> 2847523 | F66: =F41+F57 -> 3236833
E67: Résultat | F67: =F66-D66 -> 389310

Sheet Question 1
F2: Dividende actionnaire du 20 avril | H2: Terrain valeur d'utilité | I2: Installation technique | K2: VNC | L2: V marché ou valeur vénale | N2: Condanation
F3: 150000 | H3: 1250000 | I3: 1850000 | K3: 55000 | L3: 25000 | N3: 30000
B5: CALCUL PAR LES CP
B6: capitaux propres | C6: =Enoncé!H8 -> 3388830
B7: Actif fictif | C7: =Enoncé!D24+Enoncé!F16 -> 25000
B8: dividende prévu non encore versé à déduire | C8: =F3 -> 150000
B9: ANC | C9: =+C6-C7-C8 -> 3213830
B11: CALCUL PAR L'ACTIF
B12: Total actif | C12: =Enoncé!F27 -> 5684270
B13: =B7 -> Actif fictif | C13: =C7 -> 25000
B14: dettes (y compris la prov R&C) | C14: =Enoncé!H17+Enoncé!H14 -> 2295440
B15: =B8 -> dividende prévu non encore versé à déduire | C15: =F3 -> 150000
B16: ANC | C16: =C12-C13-C14-C15 -> 3213830
B19: Plus values latentes et moin values latentes
B20: PV ou MV actif | C20: VU valeur d'utilité | D20: VNC | E20: =+"+/- Values Brutes" -> +/- Values Brutes
B21: terrain | C21: =H3 -> 1250000 | D21: =Enoncé!F10 -> 850000 | E21: =C21-D21 -> 400000
B22: Installations techniques | C22: =I3 -> 1850000 | D22: =Enoncé!F12 -> 1535500 | E22: =C22-D22 -> 314500
B23: matériel de transport | C23: =L3 -> 25000 | D23: =K3 -> 55000 | E23: =C23-D23 -> -30000
B24: immos financières | C24: =+C33 -> 575000 | D24: 780000 | E24: =C24-D24 -> -205000
D25: Total | E25: =E21+E22+E23+E24 -> 479500
B27: Participation financière
B28: valeur du capital | C28: 1150000
B29: prix de la part | C29: 10
B30: nombre de titres total | C30: =C28/C29 -> 115000
B31: tx de particpation | C31: 0.5
B32: nombre de titres détenu par JV | C32: =C30*C31 -> 57500
B33: valeur au prix du cours de 10€/part | C33: 575000
C35: Impôt
B36: Fiscalité latente | C36: 0.25
B37: créance fiscale latente = actif fictif * taux d'IS | C37: =C7*C36 -> 6250
B38: dette fiscale latente = provision réglementée * taux d'IS | C38: =E23*C36 -> -7500
C43: Bilan au 31/12/N
B44: VUCB | C44: 80000
B46: 3/ La VU du crédit bail
C50: 1 | D50: 2 | E50: 3
B51: montant du contrat non actualisés | C51: 20000 | D51: =+C51 -> 20000 | E51: 20000
B52: Actualisation | C52: 0.15 | D52: 0.15 | E52: 0.15
B53: Valeur des redevances actualisés | C53: =+D51*1.15^-1 -> 17391.304 | D53: =+D51*1.15^-2 -> 15122.873 | E53: =+E51*1.15^-3 -> 13150.325
B55: VUCB au 31/12/N | C55: 80000
B56: La redevance restante | C56: =C53+D53+E53 -> 45664.502
...

Sheet Question 2
B4: Transaction comparable
B5: En euros | C5: société A | D5: société B | E5: société C | F5: société D | H5: Entreprise cible
B6: CA | C6: 5500000 | D6: 12000000 | E6: 15500000 | F6: 4875000 | H6: =Enoncé!F41 -> 3233333
B7: EBE | C7: 660000 | D7: 1550000 | E7: 1954250 | F7: 434000 | H7: =C19 -> 762133
B8: EBE/CA | C8: =C7/C6 -> 0.12 | D8: =D7/D6 -> 0.12916667 | E8: =E7/E6 -> 0.12608065 | F8: =F7/F6 -> 0.089025641 | H8: =H7/H6 -> 0.23571126
B9: Valeur des TITRES lors de la transaction passée | C9: 4818000 | D9: 12710000 | E9: 14656875 | F9: 2994600
B10: Correction du multiple du fait de la taille = décote | D10: 0.1 | E10: 0.1
B14: Multiple de l'EBE | C14: =C9/C7 -> 7.3 | D14: =D9/D7*(1-D10) -> 7.38 | E14: =E9/E7*(1-E10) -> 6.75 | F14: =F9/F7 -> 6.9
B15: Moyenne | C15: =(C14+D14+E14+F14)/4 -> 7.0825
B19: EBE | C19: =(Enoncé!F41-(Enoncé!D41+Enoncé!D43))-(Enoncé!D44+Enoncé!D45+Enoncé!D46) -> 762133
B20: Valeur d'entreprise | C20: =C19*C15 -> 5397807
B21: Provision pour risque et charges suite à la condanation | C21: ='Question 1'!N3 -> 30000
B22: dette nette | C22: =(Enoncé!H18+Enoncé!H19)-(Enoncé!D25+Enoncé!D26) -> 665000
B23: Capitaux propres | C23: =C19*C15-C22-C21 -> 4702807
